[2024-05-27 07:05:58,822] {taskinstance.py:1032} INFO - Dependencies all met for <TaskInstance: clickhouse_simple_dag.query_clickhouse manual__2024-05-27T07:05:56.858151+00:00 [queued]>
[2024-05-27 07:05:58,828] {taskinstance.py:1032} INFO - Dependencies all met for <TaskInstance: clickhouse_simple_dag.query_clickhouse manual__2024-05-27T07:05:56.858151+00:00 [queued]>
[2024-05-27 07:05:58,828] {taskinstance.py:1238} INFO - 
--------------------------------------------------------------------------------
[2024-05-27 07:05:58,828] {taskinstance.py:1239} INFO - Starting attempt 1 of 2
[2024-05-27 07:05:58,829] {taskinstance.py:1240} INFO - 
--------------------------------------------------------------------------------
[2024-05-27 07:05:58,835] {taskinstance.py:1259} INFO - Executing <Task(SimpleHttpOperator): query_clickhouse> on 2024-05-27 07:05:56.858151+00:00
[2024-05-27 07:05:58,837] {standard_task_runner.py:52} INFO - Started process 569 to run task
[2024-05-27 07:05:58,838] {standard_task_runner.py:76} INFO - Running: ['***', 'tasks', 'run', 'clickhouse_simple_dag', 'query_clickhouse', 'manual__2024-05-27T07:05:56.858151+00:00', '--job-id', '7', '--raw', '--subdir', 'DAGS_FOLDER/clickhouse_simple_dag.py', '--cfg-path', '/tmp/tmppg21s9nw', '--error-file', '/tmp/tmp66omvom2']
[2024-05-27 07:05:58,840] {standard_task_runner.py:77} INFO - Job 7: Subtask query_clickhouse
[2024-05-27 07:05:58,872] {logging_mixin.py:109} INFO - Running <TaskInstance: clickhouse_simple_dag.query_clickhouse manual__2024-05-27T07:05:56.858151+00:00 [running]> on host 5da54c086471
[2024-05-27 07:05:58,964] {taskinstance.py:1426} INFO - Exporting the following env vars:
AIRFLOW_CTX_DAG_EMAIL=your.email@example.com
AIRFLOW_CTX_DAG_OWNER=***
AIRFLOW_CTX_DAG_ID=clickhouse_simple_dag
AIRFLOW_CTX_TASK_ID=query_clickhouse
AIRFLOW_CTX_EXECUTION_DATE=2024-05-27T07:05:56.858151+00:00
AIRFLOW_CTX_DAG_RUN_ID=manual__2024-05-27T07:05:56.858151+00:00
[2024-05-27 07:05:58,964] {http.py:111} INFO - Calling HTTP method
[2024-05-27 07:05:58,970] {base.py:79} INFO - Using connection to: id: clickhouse_default. Host: clickhouse-server_2, Port: 8123, Schema: , Login: ***, Password: ***, extra: {}
[2024-05-27 07:05:58,971] {http.py:140} INFO - Sending 'POST' to url: http://clickhouse-server_2:8123
[2024-05-27 07:05:58,978] {http.py:154} ERROR - HTTP error: Forbidden
[2024-05-27 07:05:58,979] {http.py:155} ERROR - Code: 516. DB::Exception: ***: Authentication failed: password is incorrect, or there is no user with such name. (AUTHENTICATION_FAILED) (version 24.4.1.2088 (official build))

[2024-05-27 07:05:58,985] {taskinstance.py:1700} ERROR - Task failed with exception
Traceback (most recent call last):
  File "/home/airflow/.local/lib/python3.6/site-packages/airflow/providers/http/hooks/http.py", line 152, in check_response
    response.raise_for_status()
  File "/home/airflow/.local/lib/python3.6/site-packages/requests/models.py", line 953, in raise_for_status
    raise HTTPError(http_error_msg, response=self)
requests.exceptions.HTTPError: 403 Client Error: Forbidden for url: http://clickhouse-server_2:8123/

During handling of the above exception, another exception occurred:

Traceback (most recent call last):
  File "/home/airflow/.local/lib/python3.6/site-packages/airflow/models/taskinstance.py", line 1329, in _run_raw_task
    self._execute_task_with_callbacks(context)
  File "/home/airflow/.local/lib/python3.6/site-packages/airflow/models/taskinstance.py", line 1455, in _execute_task_with_callbacks
    result = self._execute_task(context, self.task)
  File "/home/airflow/.local/lib/python3.6/site-packages/airflow/models/taskinstance.py", line 1511, in _execute_task
    result = execute_callable(context=context)
  File "/home/airflow/.local/lib/python3.6/site-packages/airflow/providers/http/operators/http.py", line 113, in execute
    response = http.run(self.endpoint, self.data, self.headers, self.extra_options)
  File "/home/airflow/.local/lib/python3.6/site-packages/airflow/providers/http/hooks/http.py", line 141, in run
    return self.run_and_check(session, prepped_request, extra_options)
  File "/home/airflow/.local/lib/python3.6/site-packages/airflow/providers/http/hooks/http.py", line 198, in run_and_check
    self.check_response(response)
  File "/home/airflow/.local/lib/python3.6/site-packages/airflow/providers/http/hooks/http.py", line 156, in check_response
    raise AirflowException(str(response.status_code) + ":" + response.reason)
airflow.exceptions.AirflowException: 403:Forbidden
[2024-05-27 07:05:58,991] {taskinstance.py:1277} INFO - Marking task as UP_FOR_RETRY. dag_id=clickhouse_simple_dag, task_id=query_clickhouse, execution_date=20240527T070556, start_date=20240527T070558, end_date=20240527T070558
[2024-05-27 07:05:58,998] {standard_task_runner.py:92} ERROR - Failed to execute job 7 for task query_clickhouse
Traceback (most recent call last):
  File "/home/airflow/.local/lib/python3.6/site-packages/airflow/providers/http/hooks/http.py", line 152, in check_response
    response.raise_for_status()
  File "/home/airflow/.local/lib/python3.6/site-packages/requests/models.py", line 953, in raise_for_status
    raise HTTPError(http_error_msg, response=self)
requests.exceptions.HTTPError: 403 Client Error: Forbidden for url: http://clickhouse-server_2:8123/

During handling of the above exception, another exception occurred:

Traceback (most recent call last):
  File "/home/airflow/.local/lib/python3.6/site-packages/airflow/task/task_runner/standard_task_runner.py", line 85, in _start_by_fork
    args.func(args, dag=self.dag)
  File "/home/airflow/.local/lib/python3.6/site-packages/airflow/cli/cli_parser.py", line 48, in command
    return func(*args, **kwargs)
  File "/home/airflow/.local/lib/python3.6/site-packages/airflow/utils/cli.py", line 92, in wrapper
    return f(*args, **kwargs)
  File "/home/airflow/.local/lib/python3.6/site-packages/airflow/cli/commands/task_command.py", line 298, in task_run
    _run_task_by_selected_method(args, dag, ti)
  File "/home/airflow/.local/lib/python3.6/site-packages/airflow/cli/commands/task_command.py", line 107, in _run_task_by_selected_method
    _run_raw_task(args, ti)
  File "/home/airflow/.local/lib/python3.6/site-packages/airflow/cli/commands/task_command.py", line 184, in _run_raw_task
    error_file=args.error_file,
  File "/home/airflow/.local/lib/python3.6/site-packages/airflow/utils/session.py", line 70, in wrapper
    return func(*args, session=session, **kwargs)
  File "/home/airflow/.local/lib/python3.6/site-packages/airflow/models/taskinstance.py", line 1329, in _run_raw_task
    self._execute_task_with_callbacks(context)
  File "/home/airflow/.local/lib/python3.6/site-packages/airflow/models/taskinstance.py", line 1455, in _execute_task_with_callbacks
    result = self._execute_task(context, self.task)
  File "/home/airflow/.local/lib/python3.6/site-packages/airflow/models/taskinstance.py", line 1511, in _execute_task
    result = execute_callable(context=context)
  File "/home/airflow/.local/lib/python3.6/site-packages/airflow/providers/http/operators/http.py", line 113, in execute
    response = http.run(self.endpoint, self.data, self.headers, self.extra_options)
  File "/home/airflow/.local/lib/python3.6/site-packages/airflow/providers/http/hooks/http.py", line 141, in run
    return self.run_and_check(session, prepped_request, extra_options)
  File "/home/airflow/.local/lib/python3.6/site-packages/airflow/providers/http/hooks/http.py", line 198, in run_and_check
    self.check_response(response)
  File "/home/airflow/.local/lib/python3.6/site-packages/airflow/providers/http/hooks/http.py", line 156, in check_response
    raise AirflowException(str(response.status_code) + ":" + response.reason)
airflow.exceptions.AirflowException: 403:Forbidden
[2024-05-27 07:05:59,010] {local_task_job.py:154} INFO - Task exited with return code 1
[2024-05-27 07:05:59,031] {local_task_job.py:264} INFO - 0 downstream tasks scheduled from follow-on schedule check
