[2024-05-27 06:47:13,276] {taskinstance.py:1032} INFO - Dependencies all met for <TaskInstance: clickhouse_simple_dag.query_clickhouse scheduled__2024-05-26T06:41:42.861915+00:00 [queued]>
[2024-05-27 06:47:13,282] {taskinstance.py:1032} INFO - Dependencies all met for <TaskInstance: clickhouse_simple_dag.query_clickhouse scheduled__2024-05-26T06:41:42.861915+00:00 [queued]>
[2024-05-27 06:47:13,282] {taskinstance.py:1238} INFO - 
--------------------------------------------------------------------------------
[2024-05-27 06:47:13,282] {taskinstance.py:1239} INFO - Starting attempt 2 of 2
[2024-05-27 06:47:13,282] {taskinstance.py:1240} INFO - 
--------------------------------------------------------------------------------
[2024-05-27 06:47:13,289] {taskinstance.py:1259} INFO - Executing <Task(SimpleHttpOperator): query_clickhouse> on 2024-05-26 06:41:42.861915+00:00
[2024-05-27 06:47:13,291] {standard_task_runner.py:52} INFO - Started process 373 to run task
[2024-05-27 06:47:13,293] {standard_task_runner.py:76} INFO - Running: ['***', 'tasks', 'run', 'clickhouse_simple_dag', 'query_clickhouse', 'scheduled__2024-05-26T06:41:42.861915+00:00', '--job-id', '4', '--raw', '--subdir', 'DAGS_FOLDER/clickhouse_simple_dag.py', '--cfg-path', '/tmp/tmp7a1m64lk', '--error-file', '/tmp/tmp0_4ahynn']
[2024-05-27 06:47:13,295] {standard_task_runner.py:77} INFO - Job 4: Subtask query_clickhouse
[2024-05-27 06:47:13,324] {logging_mixin.py:109} INFO - Running <TaskInstance: clickhouse_simple_dag.query_clickhouse scheduled__2024-05-26T06:41:42.861915+00:00 [running]> on host 5da54c086471
[2024-05-27 06:47:13,411] {taskinstance.py:1426} INFO - Exporting the following env vars:
AIRFLOW_CTX_DAG_EMAIL=your.email@example.com
AIRFLOW_CTX_DAG_OWNER=***
AIRFLOW_CTX_DAG_ID=clickhouse_simple_dag
AIRFLOW_CTX_TASK_ID=query_clickhouse
AIRFLOW_CTX_EXECUTION_DATE=2024-05-26T06:41:42.861915+00:00
AIRFLOW_CTX_DAG_RUN_ID=scheduled__2024-05-26T06:41:42.861915+00:00
[2024-05-27 06:47:13,411] {http.py:111} INFO - Calling HTTP method
[2024-05-27 06:47:13,417] {base.py:79} INFO - Using connection to: id: clickhouse_default. Host: localhost, Port: 8123, Schema: db_test, Login: ***, Password: ***, extra: {}
[2024-05-27 06:47:13,417] {http.py:140} INFO - Sending 'POST' to url: db_test://localhost:8123
[2024-05-27 06:47:13,418] {taskinstance.py:1700} ERROR - Task failed with exception
Traceback (most recent call last):
  File "/home/airflow/.local/lib/python3.6/site-packages/airflow/models/taskinstance.py", line 1329, in _run_raw_task
    self._execute_task_with_callbacks(context)
  File "/home/airflow/.local/lib/python3.6/site-packages/airflow/models/taskinstance.py", line 1455, in _execute_task_with_callbacks
    result = self._execute_task(context, self.task)
  File "/home/airflow/.local/lib/python3.6/site-packages/airflow/models/taskinstance.py", line 1511, in _execute_task
    result = execute_callable(context=context)
  File "/home/airflow/.local/lib/python3.6/site-packages/airflow/providers/http/operators/http.py", line 113, in execute
    response = http.run(self.endpoint, self.data, self.headers, self.extra_options)
  File "/home/airflow/.local/lib/python3.6/site-packages/airflow/providers/http/hooks/http.py", line 141, in run
    return self.run_and_check(session, prepped_request, extra_options)
  File "/home/airflow/.local/lib/python3.6/site-packages/airflow/providers/http/hooks/http.py", line 195, in run_and_check
    response = session.send(prepped_request, **send_kwargs)
  File "/home/airflow/.local/lib/python3.6/site-packages/requests/sessions.py", line 649, in send
    adapter = self.get_adapter(url=request.url)
  File "/home/airflow/.local/lib/python3.6/site-packages/requests/sessions.py", line 742, in get_adapter
    raise InvalidSchema("No connection adapters were found for {!r}".format(url))
requests.exceptions.InvalidSchema: No connection adapters were found for 'db_test://localhost:8123'
[2024-05-27 06:47:13,426] {taskinstance.py:1277} INFO - Marking task as FAILED. dag_id=clickhouse_simple_dag, task_id=query_clickhouse, execution_date=20240526T064142, start_date=20240527T064713, end_date=20240527T064713
[2024-05-27 06:47:13,433] {standard_task_runner.py:92} ERROR - Failed to execute job 4 for task query_clickhouse
Traceback (most recent call last):
  File "/home/airflow/.local/lib/python3.6/site-packages/airflow/task/task_runner/standard_task_runner.py", line 85, in _start_by_fork
    args.func(args, dag=self.dag)
  File "/home/airflow/.local/lib/python3.6/site-packages/airflow/cli/cli_parser.py", line 48, in command
    return func(*args, **kwargs)
  File "/home/airflow/.local/lib/python3.6/site-packages/airflow/utils/cli.py", line 92, in wrapper
    return f(*args, **kwargs)
  File "/home/airflow/.local/lib/python3.6/site-packages/airflow/cli/commands/task_command.py", line 298, in task_run
    _run_task_by_selected_method(args, dag, ti)
  File "/home/airflow/.local/lib/python3.6/site-packages/airflow/cli/commands/task_command.py", line 107, in _run_task_by_selected_method
    _run_raw_task(args, ti)
  File "/home/airflow/.local/lib/python3.6/site-packages/airflow/cli/commands/task_command.py", line 184, in _run_raw_task
    error_file=args.error_file,
  File "/home/airflow/.local/lib/python3.6/site-packages/airflow/utils/session.py", line 70, in wrapper
    return func(*args, session=session, **kwargs)
  File "/home/airflow/.local/lib/python3.6/site-packages/airflow/models/taskinstance.py", line 1329, in _run_raw_task
    self._execute_task_with_callbacks(context)
  File "/home/airflow/.local/lib/python3.6/site-packages/airflow/models/taskinstance.py", line 1455, in _execute_task_with_callbacks
    result = self._execute_task(context, self.task)
  File "/home/airflow/.local/lib/python3.6/site-packages/airflow/models/taskinstance.py", line 1511, in _execute_task
    result = execute_callable(context=context)
  File "/home/airflow/.local/lib/python3.6/site-packages/airflow/providers/http/operators/http.py", line 113, in execute
    response = http.run(self.endpoint, self.data, self.headers, self.extra_options)
  File "/home/airflow/.local/lib/python3.6/site-packages/airflow/providers/http/hooks/http.py", line 141, in run
    return self.run_and_check(session, prepped_request, extra_options)
  File "/home/airflow/.local/lib/python3.6/site-packages/airflow/providers/http/hooks/http.py", line 195, in run_and_check
    response = session.send(prepped_request, **send_kwargs)
  File "/home/airflow/.local/lib/python3.6/site-packages/requests/sessions.py", line 649, in send
    adapter = self.get_adapter(url=request.url)
  File "/home/airflow/.local/lib/python3.6/site-packages/requests/sessions.py", line 742, in get_adapter
    raise InvalidSchema("No connection adapters were found for {!r}".format(url))
requests.exceptions.InvalidSchema: No connection adapters were found for 'db_test://localhost:8123'
[2024-05-27 06:47:13,465] {local_task_job.py:154} INFO - Task exited with return code 1
[2024-05-27 06:47:13,488] {local_task_job.py:264} INFO - 0 downstream tasks scheduled from follow-on schedule check
