[2024-05-27 08:17:00,311] {taskinstance.py:1032} INFO - Dependencies all met for <TaskInstance: clickhouse_script_execution.run_dag_script manual__2024-05-27T08:16:58.026666+00:00 [queued]>
[2024-05-27 08:17:00,331] {taskinstance.py:1032} INFO - Dependencies all met for <TaskInstance: clickhouse_script_execution.run_dag_script manual__2024-05-27T08:16:58.026666+00:00 [queued]>
[2024-05-27 08:17:00,332] {taskinstance.py:1238} INFO - 
--------------------------------------------------------------------------------
[2024-05-27 08:17:00,332] {taskinstance.py:1239} INFO - Starting attempt 1 of 2
[2024-05-27 08:17:00,332] {taskinstance.py:1240} INFO - 
--------------------------------------------------------------------------------
[2024-05-27 08:17:00,344] {taskinstance.py:1259} INFO - Executing <Task(PythonOperator): run_dag_script> on 2024-05-27 08:16:58.026666+00:00
[2024-05-27 08:17:00,349] {standard_task_runner.py:52} INFO - Started process 1604 to run task
[2024-05-27 08:17:00,352] {standard_task_runner.py:76} INFO - Running: ['***', 'tasks', 'run', 'clickhouse_script_execution', 'run_dag_script', 'manual__2024-05-27T08:16:58.026666+00:00', '--job-id', '21', '--raw', '--subdir', 'DAGS_FOLDER/dag_script_run_v1.py', '--cfg-path', '/tmp/tmpt20jvagb', '--error-file', '/tmp/tmpge1f766n']
[2024-05-27 08:17:00,355] {standard_task_runner.py:77} INFO - Job 21: Subtask run_dag_script
[2024-05-27 08:17:00,527] {logging_mixin.py:109} INFO - Running <TaskInstance: clickhouse_script_execution.run_dag_script manual__2024-05-27T08:16:58.026666+00:00 [running]> on host 5da54c086471
[2024-05-27 08:17:00,560] {taskinstance.py:1426} INFO - Exporting the following env vars:
AIRFLOW_CTX_DAG_EMAIL=your.email@example.com
AIRFLOW_CTX_DAG_OWNER=***
AIRFLOW_CTX_DAG_ID=clickhouse_script_execution
AIRFLOW_CTX_TASK_ID=run_dag_script
AIRFLOW_CTX_EXECUTION_DATE=2024-05-27T08:16:58.026666+00:00
AIRFLOW_CTX_DAG_RUN_ID=manual__2024-05-27T08:16:58.026666+00:00
[2024-05-27 08:17:00,975] {connection.py:355} WARNING - Failed to connect to localhost:9000
Traceback (most recent call last):
  File "/home/airflow/.local/lib/python3.6/site-packages/clickhouse_driver/connection.py", line 342, in connect
    return self._init_connection(host, port)
  File "/home/airflow/.local/lib/python3.6/site-packages/clickhouse_driver/connection.py", line 306, in _init_connection
    self.socket = self._create_socket(host, port)
  File "/home/airflow/.local/lib/python3.6/site-packages/clickhouse_driver/connection.py", line 278, in _create_socket
    raise err
  File "/home/airflow/.local/lib/python3.6/site-packages/clickhouse_driver/connection.py", line 269, in _create_socket
    sock.connect(sa)
OSError: [Errno 99] Cannot assign requested address
[2024-05-27 08:17:00,975] {taskinstance.py:1700} ERROR - Task failed with exception
Traceback (most recent call last):
  File "/home/airflow/.local/lib/python3.6/site-packages/airflow/models/taskinstance.py", line 1329, in _run_raw_task
    self._execute_task_with_callbacks(context)
  File "/home/airflow/.local/lib/python3.6/site-packages/airflow/models/taskinstance.py", line 1455, in _execute_task_with_callbacks
    result = self._execute_task(context, self.task)
  File "/home/airflow/.local/lib/python3.6/site-packages/airflow/models/taskinstance.py", line 1511, in _execute_task
    result = execute_callable(context=context)
  File "/home/airflow/.local/lib/python3.6/site-packages/airflow/operators/python.py", line 174, in execute
    return_value = self.execute_callable()
  File "/home/airflow/.local/lib/python3.6/site-packages/airflow/operators/python.py", line 185, in execute_callable
    return self.python_callable(*self.op_args, **self.op_kwargs)
  File "/opt/airflow/dags/dag_script_run_v1.py", line 9, in run_python_script
    exec(open('/opt/airflow/dags/dag_script.py').read())
  File "<string>", line 8, in <module>
  File "/home/airflow/.local/lib/python3.6/site-packages/clickhouse_driver/client.py", line 345, in execute
    with self.disconnect_on_error(query, settings):
  File "/usr/local/lib/python3.6/contextlib.py", line 81, in __enter__
    return next(self.gen)
  File "/home/airflow/.local/lib/python3.6/site-packages/clickhouse_driver/client.py", line 289, in disconnect_on_error
    self.establish_connection(settings)
  File "/home/airflow/.local/lib/python3.6/site-packages/clickhouse_driver/client.py", line 276, in establish_connection
    self.connection.force_connect()
  File "/home/airflow/.local/lib/python3.6/site-packages/clickhouse_driver/connection.py", line 235, in force_connect
    self.connect()
  File "/home/airflow/.local/lib/python3.6/site-packages/clickhouse_driver/connection.py", line 363, in connect
    raise err
clickhouse_driver.errors.NetworkError: Code: 210. Cannot assign requested address (localhost:9000)
[2024-05-27 08:17:00,988] {taskinstance.py:1277} INFO - Marking task as UP_FOR_RETRY. dag_id=clickhouse_script_execution, task_id=run_dag_script, execution_date=20240527T081658, start_date=20240527T081700, end_date=20240527T081700
[2024-05-27 08:17:00,997] {standard_task_runner.py:92} ERROR - Failed to execute job 21 for task run_dag_script
Traceback (most recent call last):
  File "/home/airflow/.local/lib/python3.6/site-packages/airflow/task/task_runner/standard_task_runner.py", line 85, in _start_by_fork
    args.func(args, dag=self.dag)
  File "/home/airflow/.local/lib/python3.6/site-packages/airflow/cli/cli_parser.py", line 48, in command
    return func(*args, **kwargs)
  File "/home/airflow/.local/lib/python3.6/site-packages/airflow/utils/cli.py", line 92, in wrapper
    return f(*args, **kwargs)
  File "/home/airflow/.local/lib/python3.6/site-packages/airflow/cli/commands/task_command.py", line 298, in task_run
    _run_task_by_selected_method(args, dag, ti)
  File "/home/airflow/.local/lib/python3.6/site-packages/airflow/cli/commands/task_command.py", line 107, in _run_task_by_selected_method
    _run_raw_task(args, ti)
  File "/home/airflow/.local/lib/python3.6/site-packages/airflow/cli/commands/task_command.py", line 184, in _run_raw_task
    error_file=args.error_file,
  File "/home/airflow/.local/lib/python3.6/site-packages/airflow/utils/session.py", line 70, in wrapper
    return func(*args, session=session, **kwargs)
  File "/home/airflow/.local/lib/python3.6/site-packages/airflow/models/taskinstance.py", line 1329, in _run_raw_task
    self._execute_task_with_callbacks(context)
  File "/home/airflow/.local/lib/python3.6/site-packages/airflow/models/taskinstance.py", line 1455, in _execute_task_with_callbacks
    result = self._execute_task(context, self.task)
  File "/home/airflow/.local/lib/python3.6/site-packages/airflow/models/taskinstance.py", line 1511, in _execute_task
    result = execute_callable(context=context)
  File "/home/airflow/.local/lib/python3.6/site-packages/airflow/operators/python.py", line 174, in execute
    return_value = self.execute_callable()
  File "/home/airflow/.local/lib/python3.6/site-packages/airflow/operators/python.py", line 185, in execute_callable
    return self.python_callable(*self.op_args, **self.op_kwargs)
  File "/opt/airflow/dags/dag_script_run_v1.py", line 9, in run_python_script
    exec(open('/opt/airflow/dags/dag_script.py').read())
  File "<string>", line 8, in <module>
  File "/home/airflow/.local/lib/python3.6/site-packages/clickhouse_driver/client.py", line 345, in execute
    with self.disconnect_on_error(query, settings):
  File "/usr/local/lib/python3.6/contextlib.py", line 81, in __enter__
    return next(self.gen)
  File "/home/airflow/.local/lib/python3.6/site-packages/clickhouse_driver/client.py", line 289, in disconnect_on_error
    self.establish_connection(settings)
  File "/home/airflow/.local/lib/python3.6/site-packages/clickhouse_driver/client.py", line 276, in establish_connection
    self.connection.force_connect()
  File "/home/airflow/.local/lib/python3.6/site-packages/clickhouse_driver/connection.py", line 235, in force_connect
    self.connect()
  File "/home/airflow/.local/lib/python3.6/site-packages/clickhouse_driver/connection.py", line 363, in connect
    raise err
clickhouse_driver.errors.NetworkError: Code: 210. Cannot assign requested address (localhost:9000)
[2024-05-27 08:17:01,046] {local_task_job.py:154} INFO - Task exited with return code 1
[2024-05-27 08:17:01,254] {local_task_job.py:264} INFO - 0 downstream tasks scheduled from follow-on schedule check
