[2024-05-27 08:03:36,341] {taskinstance.py:1032} INFO - Dependencies all met for <TaskInstance: clickhouse_script_execution.run_dag_script manual__2024-05-27T08:03:35.226242+00:00 [queued]>
[2024-05-27 08:03:36,349] {taskinstance.py:1032} INFO - Dependencies all met for <TaskInstance: clickhouse_script_execution.run_dag_script manual__2024-05-27T08:03:35.226242+00:00 [queued]>
[2024-05-27 08:03:36,350] {taskinstance.py:1238} INFO - 
--------------------------------------------------------------------------------
[2024-05-27 08:03:36,351] {taskinstance.py:1239} INFO - Starting attempt 1 of 2
[2024-05-27 08:03:36,351] {taskinstance.py:1240} INFO - 
--------------------------------------------------------------------------------
[2024-05-27 08:03:36,360] {taskinstance.py:1259} INFO - Executing <Task(PythonOperator): run_dag_script> on 2024-05-27 08:03:35.226242+00:00
[2024-05-27 08:03:36,362] {standard_task_runner.py:52} INFO - Started process 1305 to run task
[2024-05-27 08:03:36,365] {standard_task_runner.py:76} INFO - Running: ['***', 'tasks', 'run', 'clickhouse_script_execution', 'run_dag_script', 'manual__2024-05-27T08:03:35.226242+00:00', '--job-id', '12', '--raw', '--subdir', 'DAGS_FOLDER/dag_script_run_v1.py', '--cfg-path', '/tmp/tmph7ejmfqk', '--error-file', '/tmp/tmpfqta23zi']
[2024-05-27 08:03:36,367] {standard_task_runner.py:77} INFO - Job 12: Subtask run_dag_script
[2024-05-27 08:03:36,405] {logging_mixin.py:109} INFO - Running <TaskInstance: clickhouse_script_execution.run_dag_script manual__2024-05-27T08:03:35.226242+00:00 [running]> on host 5da54c086471
[2024-05-27 08:03:36,530] {taskinstance.py:1426} INFO - Exporting the following env vars:
AIRFLOW_CTX_DAG_EMAIL=your.email@example.com
AIRFLOW_CTX_DAG_OWNER=***
AIRFLOW_CTX_DAG_ID=clickhouse_script_execution
AIRFLOW_CTX_TASK_ID=run_dag_script
AIRFLOW_CTX_EXECUTION_DATE=2024-05-27T08:03:35.226242+00:00
AIRFLOW_CTX_DAG_RUN_ID=manual__2024-05-27T08:03:35.226242+00:00
[2024-05-27 08:03:36,532] {taskinstance.py:1700} ERROR - Task failed with exception
Traceback (most recent call last):
  File "/home/airflow/.local/lib/python3.6/site-packages/airflow/models/taskinstance.py", line 1329, in _run_raw_task
    self._execute_task_with_callbacks(context)
  File "/home/airflow/.local/lib/python3.6/site-packages/airflow/models/taskinstance.py", line 1455, in _execute_task_with_callbacks
    result = self._execute_task(context, self.task)
  File "/home/airflow/.local/lib/python3.6/site-packages/airflow/models/taskinstance.py", line 1511, in _execute_task
    result = execute_callable(context=context)
  File "/home/airflow/.local/lib/python3.6/site-packages/airflow/operators/python.py", line 174, in execute
    return_value = self.execute_callable()
  File "/home/airflow/.local/lib/python3.6/site-packages/airflow/operators/python.py", line 185, in execute_callable
    return self.python_callable(*self.op_args, **self.op_kwargs)
  File "/opt/airflow/dags/dag_script_run_v1.py", line 9, in run_python_script
    exec(open('dag_script.py').read())
FileNotFoundError: [Errno 2] No such file or directory: 'dag_script.py'
[2024-05-27 08:03:36,545] {taskinstance.py:1277} INFO - Marking task as UP_FOR_RETRY. dag_id=clickhouse_script_execution, task_id=run_dag_script, execution_date=20240527T080335, start_date=20240527T080336, end_date=20240527T080336
[2024-05-27 08:03:36,557] {standard_task_runner.py:92} ERROR - Failed to execute job 12 for task run_dag_script
Traceback (most recent call last):
  File "/home/airflow/.local/lib/python3.6/site-packages/airflow/task/task_runner/standard_task_runner.py", line 85, in _start_by_fork
    args.func(args, dag=self.dag)
  File "/home/airflow/.local/lib/python3.6/site-packages/airflow/cli/cli_parser.py", line 48, in command
    return func(*args, **kwargs)
  File "/home/airflow/.local/lib/python3.6/site-packages/airflow/utils/cli.py", line 92, in wrapper
    return f(*args, **kwargs)
  File "/home/airflow/.local/lib/python3.6/site-packages/airflow/cli/commands/task_command.py", line 298, in task_run
    _run_task_by_selected_method(args, dag, ti)
  File "/home/airflow/.local/lib/python3.6/site-packages/airflow/cli/commands/task_command.py", line 107, in _run_task_by_selected_method
    _run_raw_task(args, ti)
  File "/home/airflow/.local/lib/python3.6/site-packages/airflow/cli/commands/task_command.py", line 184, in _run_raw_task
    error_file=args.error_file,
  File "/home/airflow/.local/lib/python3.6/site-packages/airflow/utils/session.py", line 70, in wrapper
    return func(*args, session=session, **kwargs)
  File "/home/airflow/.local/lib/python3.6/site-packages/airflow/models/taskinstance.py", line 1329, in _run_raw_task
    self._execute_task_with_callbacks(context)
  File "/home/airflow/.local/lib/python3.6/site-packages/airflow/models/taskinstance.py", line 1455, in _execute_task_with_callbacks
    result = self._execute_task(context, self.task)
  File "/home/airflow/.local/lib/python3.6/site-packages/airflow/models/taskinstance.py", line 1511, in _execute_task
    result = execute_callable(context=context)
  File "/home/airflow/.local/lib/python3.6/site-packages/airflow/operators/python.py", line 174, in execute
    return_value = self.execute_callable()
  File "/home/airflow/.local/lib/python3.6/site-packages/airflow/operators/python.py", line 185, in execute_callable
    return self.python_callable(*self.op_args, **self.op_kwargs)
  File "/opt/airflow/dags/dag_script_run_v1.py", line 9, in run_python_script
    exec(open('dag_script.py').read())
FileNotFoundError: [Errno 2] No such file or directory: 'dag_script.py'
[2024-05-27 08:03:36,578] {local_task_job.py:154} INFO - Task exited with return code 1
[2024-05-27 08:03:36,605] {local_task_job.py:264} INFO - 0 downstream tasks scheduled from follow-on schedule check
