[2024-05-27 06:57:50,471] {taskinstance.py:1032} INFO - Dependencies all met for <TaskInstance: clickhouse_simple_dag.query_clickhouse manual__2024-05-27T06:57:49.002366+00:00 [queued]>
[2024-05-27 06:57:50,478] {taskinstance.py:1032} INFO - Dependencies all met for <TaskInstance: clickhouse_simple_dag.query_clickhouse manual__2024-05-27T06:57:49.002366+00:00 [queued]>
[2024-05-27 06:57:50,479] {taskinstance.py:1238} INFO - 
--------------------------------------------------------------------------------
[2024-05-27 06:57:50,479] {taskinstance.py:1239} INFO - Starting attempt 1 of 2
[2024-05-27 06:57:50,479] {taskinstance.py:1240} INFO - 
--------------------------------------------------------------------------------
[2024-05-27 06:57:50,486] {taskinstance.py:1259} INFO - Executing <Task(SimpleHttpOperator): query_clickhouse> on 2024-05-27 06:57:49.002366+00:00
[2024-05-27 06:57:50,488] {standard_task_runner.py:52} INFO - Started process 485 to run task
[2024-05-27 06:57:50,490] {standard_task_runner.py:76} INFO - Running: ['***', 'tasks', 'run', 'clickhouse_simple_dag', 'query_clickhouse', 'manual__2024-05-27T06:57:49.002366+00:00', '--job-id', '5', '--raw', '--subdir', 'DAGS_FOLDER/clickhouse_simple_dag.py', '--cfg-path', '/tmp/tmpyuc_1t0l', '--error-file', '/tmp/tmpphil0na_']
[2024-05-27 06:57:50,491] {standard_task_runner.py:77} INFO - Job 5: Subtask query_clickhouse
[2024-05-27 06:57:50,521] {logging_mixin.py:109} INFO - Running <TaskInstance: clickhouse_simple_dag.query_clickhouse manual__2024-05-27T06:57:49.002366+00:00 [running]> on host 5da54c086471
[2024-05-27 06:57:50,610] {taskinstance.py:1426} INFO - Exporting the following env vars:
AIRFLOW_CTX_DAG_EMAIL=your.email@example.com
AIRFLOW_CTX_DAG_OWNER=***
AIRFLOW_CTX_DAG_ID=clickhouse_simple_dag
AIRFLOW_CTX_TASK_ID=query_clickhouse
AIRFLOW_CTX_EXECUTION_DATE=2024-05-27T06:57:49.002366+00:00
AIRFLOW_CTX_DAG_RUN_ID=manual__2024-05-27T06:57:49.002366+00:00
[2024-05-27 06:57:50,610] {http.py:111} INFO - Calling HTTP method
[2024-05-27 06:57:50,617] {base.py:79} INFO - Using connection to: id: clickhouse_default. Host: localhost, Port: 8123, Schema: , Login: ***, Password: ***, extra: {}
[2024-05-27 06:57:50,618] {http.py:140} INFO - Sending 'POST' to url: http://localhost:8123
[2024-05-27 06:57:50,621] {http.py:202} WARNING - HTTPConnectionPool(host='localhost', port=8123): Max retries exceeded with url: / (Caused by NewConnectionError('<urllib3.connection.HTTPConnection object at 0x7f903bfac630>: Failed to establish a new connection: [Errno 111] Connection refused',)) Tenacity will retry to execute the operation
[2024-05-27 06:57:50,621] {taskinstance.py:1700} ERROR - Task failed with exception
Traceback (most recent call last):
  File "/home/airflow/.local/lib/python3.6/site-packages/urllib3/connection.py", line 175, in _new_conn
    (self._dns_host, self.port), self.timeout, **extra_kw
  File "/home/airflow/.local/lib/python3.6/site-packages/urllib3/util/connection.py", line 96, in create_connection
    raise err
  File "/home/airflow/.local/lib/python3.6/site-packages/urllib3/util/connection.py", line 86, in create_connection
    sock.connect(sa)
ConnectionRefusedError: [Errno 111] Connection refused

During handling of the above exception, another exception occurred:

Traceback (most recent call last):
  File "/home/airflow/.local/lib/python3.6/site-packages/urllib3/connectionpool.py", line 706, in urlopen
    chunked=chunked,
  File "/home/airflow/.local/lib/python3.6/site-packages/urllib3/connectionpool.py", line 394, in _make_request
    conn.request(method, url, **httplib_request_kw)
  File "/home/airflow/.local/lib/python3.6/site-packages/urllib3/connection.py", line 239, in request
    super(HTTPConnection, self).request(method, url, body=body, headers=headers)
  File "/usr/local/lib/python3.6/http/client.py", line 1291, in request
    self._send_request(method, url, body, headers, encode_chunked)
  File "/usr/local/lib/python3.6/http/client.py", line 1337, in _send_request
    self.endheaders(body, encode_chunked=encode_chunked)
  File "/usr/local/lib/python3.6/http/client.py", line 1286, in endheaders
    self._send_output(message_body, encode_chunked=encode_chunked)
  File "/usr/local/lib/python3.6/http/client.py", line 1046, in _send_output
    self.send(msg)
  File "/usr/local/lib/python3.6/http/client.py", line 984, in send
    self.connect()
  File "/home/airflow/.local/lib/python3.6/site-packages/urllib3/connection.py", line 205, in connect
    conn = self._new_conn()
  File "/home/airflow/.local/lib/python3.6/site-packages/urllib3/connection.py", line 187, in _new_conn
    self, "Failed to establish a new connection: %s" % e
urllib3.exceptions.NewConnectionError: <urllib3.connection.HTTPConnection object at 0x7f903bfac630>: Failed to establish a new connection: [Errno 111] Connection refused

During handling of the above exception, another exception occurred:

Traceback (most recent call last):
  File "/home/airflow/.local/lib/python3.6/site-packages/requests/adapters.py", line 449, in send
    timeout=timeout
  File "/home/airflow/.local/lib/python3.6/site-packages/urllib3/connectionpool.py", line 756, in urlopen
    method, url, error=e, _pool=self, _stacktrace=sys.exc_info()[2]
  File "/home/airflow/.local/lib/python3.6/site-packages/urllib3/util/retry.py", line 574, in increment
    raise MaxRetryError(_pool, url, error or ResponseError(cause))
urllib3.exceptions.MaxRetryError: HTTPConnectionPool(host='localhost', port=8123): Max retries exceeded with url: / (Caused by NewConnectionError('<urllib3.connection.HTTPConnection object at 0x7f903bfac630>: Failed to establish a new connection: [Errno 111] Connection refused',))

During handling of the above exception, another exception occurred:

Traceback (most recent call last):
  File "/home/airflow/.local/lib/python3.6/site-packages/airflow/models/taskinstance.py", line 1329, in _run_raw_task
    self._execute_task_with_callbacks(context)
  File "/home/airflow/.local/lib/python3.6/site-packages/airflow/models/taskinstance.py", line 1455, in _execute_task_with_callbacks
    result = self._execute_task(context, self.task)
  File "/home/airflow/.local/lib/python3.6/site-packages/airflow/models/taskinstance.py", line 1511, in _execute_task
    result = execute_callable(context=context)
  File "/home/airflow/.local/lib/python3.6/site-packages/airflow/providers/http/operators/http.py", line 113, in execute
    response = http.run(self.endpoint, self.data, self.headers, self.extra_options)
  File "/home/airflow/.local/lib/python3.6/site-packages/airflow/providers/http/hooks/http.py", line 141, in run
    return self.run_and_check(session, prepped_request, extra_options)
  File "/home/airflow/.local/lib/python3.6/site-packages/airflow/providers/http/hooks/http.py", line 203, in run_and_check
    raise ex
  File "/home/airflow/.local/lib/python3.6/site-packages/airflow/providers/http/hooks/http.py", line 195, in run_and_check
    response = session.send(prepped_request, **send_kwargs)
  File "/home/airflow/.local/lib/python3.6/site-packages/requests/sessions.py", line 655, in send
    r = adapter.send(request, **kwargs)
  File "/home/airflow/.local/lib/python3.6/site-packages/requests/adapters.py", line 516, in send
    raise ConnectionError(e, request=request)
requests.exceptions.ConnectionError: HTTPConnectionPool(host='localhost', port=8123): Max retries exceeded with url: / (Caused by NewConnectionError('<urllib3.connection.HTTPConnection object at 0x7f903bfac630>: Failed to establish a new connection: [Errno 111] Connection refused',))
[2024-05-27 06:57:50,632] {taskinstance.py:1277} INFO - Marking task as UP_FOR_RETRY. dag_id=clickhouse_simple_dag, task_id=query_clickhouse, execution_date=20240527T065749, start_date=20240527T065750, end_date=20240527T065750
[2024-05-27 06:57:50,640] {standard_task_runner.py:92} ERROR - Failed to execute job 5 for task query_clickhouse
Traceback (most recent call last):
  File "/home/airflow/.local/lib/python3.6/site-packages/urllib3/connection.py", line 175, in _new_conn
    (self._dns_host, self.port), self.timeout, **extra_kw
  File "/home/airflow/.local/lib/python3.6/site-packages/urllib3/util/connection.py", line 96, in create_connection
    raise err
  File "/home/airflow/.local/lib/python3.6/site-packages/urllib3/util/connection.py", line 86, in create_connection
    sock.connect(sa)
ConnectionRefusedError: [Errno 111] Connection refused

During handling of the above exception, another exception occurred:

Traceback (most recent call last):
  File "/home/airflow/.local/lib/python3.6/site-packages/urllib3/connectionpool.py", line 706, in urlopen
    chunked=chunked,
  File "/home/airflow/.local/lib/python3.6/site-packages/urllib3/connectionpool.py", line 394, in _make_request
    conn.request(method, url, **httplib_request_kw)
  File "/home/airflow/.local/lib/python3.6/site-packages/urllib3/connection.py", line 239, in request
    super(HTTPConnection, self).request(method, url, body=body, headers=headers)
  File "/usr/local/lib/python3.6/http/client.py", line 1291, in request
    self._send_request(method, url, body, headers, encode_chunked)
  File "/usr/local/lib/python3.6/http/client.py", line 1337, in _send_request
    self.endheaders(body, encode_chunked=encode_chunked)
  File "/usr/local/lib/python3.6/http/client.py", line 1286, in endheaders
    self._send_output(message_body, encode_chunked=encode_chunked)
  File "/usr/local/lib/python3.6/http/client.py", line 1046, in _send_output
    self.send(msg)
  File "/usr/local/lib/python3.6/http/client.py", line 984, in send
    self.connect()
  File "/home/airflow/.local/lib/python3.6/site-packages/urllib3/connection.py", line 205, in connect
    conn = self._new_conn()
  File "/home/airflow/.local/lib/python3.6/site-packages/urllib3/connection.py", line 187, in _new_conn
    self, "Failed to establish a new connection: %s" % e
urllib3.exceptions.NewConnectionError: <urllib3.connection.HTTPConnection object at 0x7f903bfac630>: Failed to establish a new connection: [Errno 111] Connection refused

During handling of the above exception, another exception occurred:

Traceback (most recent call last):
  File "/home/airflow/.local/lib/python3.6/site-packages/requests/adapters.py", line 449, in send
    timeout=timeout
  File "/home/airflow/.local/lib/python3.6/site-packages/urllib3/connectionpool.py", line 756, in urlopen
    method, url, error=e, _pool=self, _stacktrace=sys.exc_info()[2]
  File "/home/airflow/.local/lib/python3.6/site-packages/urllib3/util/retry.py", line 574, in increment
    raise MaxRetryError(_pool, url, error or ResponseError(cause))
urllib3.exceptions.MaxRetryError: HTTPConnectionPool(host='localhost', port=8123): Max retries exceeded with url: / (Caused by NewConnectionError('<urllib3.connection.HTTPConnection object at 0x7f903bfac630>: Failed to establish a new connection: [Errno 111] Connection refused',))

During handling of the above exception, another exception occurred:

Traceback (most recent call last):
  File "/home/airflow/.local/lib/python3.6/site-packages/airflow/task/task_runner/standard_task_runner.py", line 85, in _start_by_fork
    args.func(args, dag=self.dag)
  File "/home/airflow/.local/lib/python3.6/site-packages/airflow/cli/cli_parser.py", line 48, in command
    return func(*args, **kwargs)
  File "/home/airflow/.local/lib/python3.6/site-packages/airflow/utils/cli.py", line 92, in wrapper
    return f(*args, **kwargs)
  File "/home/airflow/.local/lib/python3.6/site-packages/airflow/cli/commands/task_command.py", line 298, in task_run
    _run_task_by_selected_method(args, dag, ti)
  File "/home/airflow/.local/lib/python3.6/site-packages/airflow/cli/commands/task_command.py", line 107, in _run_task_by_selected_method
    _run_raw_task(args, ti)
  File "/home/airflow/.local/lib/python3.6/site-packages/airflow/cli/commands/task_command.py", line 184, in _run_raw_task
    error_file=args.error_file,
  File "/home/airflow/.local/lib/python3.6/site-packages/airflow/utils/session.py", line 70, in wrapper
    return func(*args, session=session, **kwargs)
  File "/home/airflow/.local/lib/python3.6/site-packages/airflow/models/taskinstance.py", line 1329, in _run_raw_task
    self._execute_task_with_callbacks(context)
  File "/home/airflow/.local/lib/python3.6/site-packages/airflow/models/taskinstance.py", line 1455, in _execute_task_with_callbacks
    result = self._execute_task(context, self.task)
  File "/home/airflow/.local/lib/python3.6/site-packages/airflow/models/taskinstance.py", line 1511, in _execute_task
    result = execute_callable(context=context)
  File "/home/airflow/.local/lib/python3.6/site-packages/airflow/providers/http/operators/http.py", line 113, in execute
    response = http.run(self.endpoint, self.data, self.headers, self.extra_options)
  File "/home/airflow/.local/lib/python3.6/site-packages/airflow/providers/http/hooks/http.py", line 141, in run
    return self.run_and_check(session, prepped_request, extra_options)
  File "/home/airflow/.local/lib/python3.6/site-packages/airflow/providers/http/hooks/http.py", line 203, in run_and_check
    raise ex
  File "/home/airflow/.local/lib/python3.6/site-packages/airflow/providers/http/hooks/http.py", line 195, in run_and_check
    response = session.send(prepped_request, **send_kwargs)
  File "/home/airflow/.local/lib/python3.6/site-packages/requests/sessions.py", line 655, in send
    r = adapter.send(request, **kwargs)
  File "/home/airflow/.local/lib/python3.6/site-packages/requests/adapters.py", line 516, in send
    raise ConnectionError(e, request=request)
requests.exceptions.ConnectionError: HTTPConnectionPool(host='localhost', port=8123): Max retries exceeded with url: / (Caused by NewConnectionError('<urllib3.connection.HTTPConnection object at 0x7f903bfac630>: Failed to establish a new connection: [Errno 111] Connection refused',))
[2024-05-27 06:57:50,662] {local_task_job.py:154} INFO - Task exited with return code 1
[2024-05-27 06:57:50,684] {local_task_job.py:264} INFO - 0 downstream tasks scheduled from follow-on schedule check
